<?xml version="0.0" ?>
<robot name="spider_robot" xmlns:xacro="http://www.ros.org/wiki/xacro">

    <link name="body">
        <visual>
            <origin xyz="0 0 0.05" rpy="0 0 0"/>
            <geometry>
                <box size="1.5 1.0 0.1" />
            </geometry>
        </visual>
        <collision>
            <origin xyz="0 0 0.05" rpy="0 0 0"/>
            <geometry>
                <box size="1.5 1.0 0.1" />
            </geometry>
        </collision>
        <inertial>
            <origin xyz="0 0 0.05" rpy="0 0 0"/>
            <mass value="0.3" />
            <inertia ixx="0.025" ixy="0.0" ixz="0.0" iyy="0.08" iyz="0.0" izz="0.57" />
        </inertial>
    </link>

    <joint name="FR_joint_1" type="revolute">
        <origin xyz="0.75 0.5 0.05"/>
        <parent link="body"/>
        <child link="FR_leg"/>
        <axis xyz="0 0 -1"/>
        <limit lower = "0" upper = "3.14" velocity = "100" efforts = "100" />
    </joint>

    <link name="FR_leg" >
		<inertial>
				<origin rpy = "1.57 -1.57 0" xyz = "0 0.25 0" />
			 <mass value = "0.1" />
			<inertia ixx = "0.02" ixy = "0" ixz = "0" iyy = "0.02" iyz = "0" izz = "0.02" />
		</inertial>
		<collision>
				<origin rpy = "1.57 -1.57 0" xyz = "0 0.25 0" />
			<geometry>
				<capsule length="0.5" radius="0.05"/>
			</geometry>
		</collision>
	</link>

    <joint name="FR_joint_2" type="revolute">
        <origin xyz="0 0.5 0"/>
        <parent link="FR_leg"/>
        <child link="FR_feet"/>
        <axis xyz="1 0 0"/>
        <limit lower = "0" upper = "3.14" velocity = "100" efforts = "100" />
    </joint>

    <link name="FR_feet" >
		<inertial>
				<origin rpy = "0 0 0" xyz = "0 0 -0.25" />
			 <mass value = "0.1" />
			<inertia ixx = "0.02" ixy = "0" ixz = "0" iyy = "0.02" iyz = "0" izz = "0.02" />
		</inertial>
		<collision>
				<origin rpy = "0 0 0" xyz = "0 0 -0.25" />
			<geometry>
				<capsule length="0.5" radius="0.05"/>
			</geometry>
		</collision>
	</link>

    <joint name="FL_joint_1" type="revolute">
        <origin xyz="-0.75 0.5 0.05"/>
        <parent link="body"/>
        <child link="FL_leg"/>
        <axis xyz="0 0 1"/>
        <limit lower = "0" upper = "3.14" velocity = "100" efforts = "100" />
    </joint>

    <link name="FL_leg" >
		<inertial>
				<origin rpy = "0 -1.57 1.57" xyz = "0 0.25 0" />
			 <mass value = "0.1" />
			<inertia ixx = "0.02" ixy = "0" ixz = "0" iyy = "0.02" iyz = "0" izz = "0.02" />
		</inertial>
		<collision>
				<origin rpy = "0 -1.57 1.57" xyz = "0 0.25 0" />
			<geometry>
				<capsule length="0.5" radius="0.05"/>
			</geometry>
		</collision>
	</link>

    <joint name="FL_joint_2" type="revolute">
        <origin xyz="0 0.5 0"/>
        <parent link="FL_leg"/>
        <child link="FL_feet"/>
        <axis xyz="1 0 0"/>
        <limit lower = "0" upper = "3.14" velocity = "100" efforts = "100" />
    </joint>

    <link name="FL_feet" >
		<inertial>
				<origin rpy = "0 0 0" xyz = "0 0 -0.25" />
			 <mass value = "0.1" />
			<inertia ixx = "0.02" ixy = "0" ixz = "0" iyy = "0.02" iyz = "0" izz = "0.02" />
		</inertial>
		<collision>
				<origin rpy = "0 0 0" xyz = "0 0 -0.25" />
			<geometry>
				<capsule length="0.5" radius="0.05"/>
			</geometry>
		</collision>
	</link>

    <joint name="RR_joint_1" type="revolute">
        <origin xyz="0.75 -0.5 0.05"/>
        <parent link="body"/>
        <child link="RR_leg"/>
        <axis xyz="0 0 1"/>
        <limit lower = "0" upper = "3.14" velocity = "100" efforts = "100" />
    </joint>

    <link name="RR_leg" >
		<inertial>
				<origin rpy = "-1.57 -1.57 0" xyz = "0 -0.25 0" />
			 <mass value = "0.1" />
			<inertia ixx = "0.02" ixy = "0" ixz = "0" iyy = "0.02" iyz = "0" izz = "0.02" />
		</inertial>
		<collision>
				<origin rpy = "-1.57 -1.57 0" xyz = "0 -0.25 0" />
			<geometry>
				<capsule length="0.5" radius="0.05"/>
			</geometry>
		</collision>
	</link>

    <joint name="RR_joint_2" type="revolute">
        <origin xyz="0 -0.5 0"/>
        <parent link="RR_leg"/>
        <child link="RR_feet"/>
        <axis xyz="-1 0 0"/>
        <limit lower = "0" upper = "3.14" velocity = "100" efforts = "100" />
    </joint>

    <link name="RR_feet">
		<inertial>
				<origin rpy = "0 0 0" xyz = "0 0 -0.25" />
			 <mass value = "0.1" />
			<inertia ixx = "0.02" ixy = "0" ixz = "0" iyy = "0.02" iyz = "0" izz = "0.02" />
		</inertial>
		<collision>
				<origin rpy = "0 0 0" xyz = "0 0 -0.25" />
			<geometry>
				<capsule length="0.5" radius="0.05"/>
			</geometry>
		</collision>
	</link>

    <joint name="RL_joint_1" type="revolute">
        <origin xyz="-0.75 -0.5 0.05"/>
        <parent link="body"/>
        <child link="RL_leg"/>
        <axis xyz="0 0 -1"/>
        <limit lower = "0" upper = "3.14" velocity = "100" efforts = "100" />
    </joint>

    <link name="RL_leg" >
		<inertial>
				<origin rpy = "0 -1.57 1.57" xyz = "0 -0.25 0" />
			    <mass value = "0.1" />
			<inertia ixx = "0.02" ixy = "0" ixz = "0" iyy = "0.02" iyz = "0" izz = "0.02" />
		</inertial>
		<collision>
				<origin rpy = "0 -1.57 1.57" xyz = "0 -0.25 0" />
			<geometry>
				<capsule length="0.5" radius="0.05"/>
			</geometry>
		</collision>
	</link>

    <joint name="RL_joint_2" type="revolute">
        <origin xyz="0 -0.5 0"/>
        <parent link="RL_leg"/>
        <child link="RL_feet"/>
        <axis xyz="-1 0 0"/>
        <limit lower = "0" upper = "3.14" velocity = "100" efforts = "100" />
    </joint>

    <link name="RL_feet">
		<inertial>
				<origin rpy = "0 0 0" xyz = "0 0 -0.25" />
			 <mass value = "0.1" />
			<inertia ixx = "0.02" ixy = "0" ixz = "0" iyy = "0.02" iyz = "0" izz = "0.02" />
		</inertial>
		<collision>
				<origin rpy = "0 0 0" xyz = "0 0 -0.25" />
			<geometry>
				<capsule length="0.5" radius="0.05"/>
			</geometry>
		</collision>
	</link>

</robot>